[2023-10-16 18:51:48,676] {c:\users\jj_ca\onedrive\documents\github\project-phishing\venv\lib\site-packages\flask\app.py:1414} ERROR - Exception on /auth/register [POST]
Traceback (most recent call last):
  File "c:\users\jj_ca\onedrive\documents\github\project-phishing\venv\lib\site-packages\sqlalchemy\engine\base.py", line 145, in __init__
    self._dbapi_connection = engine.raw_connection()
  File "c:\users\jj_ca\onedrive\documents\github\project-phishing\venv\lib\site-packages\sqlalchemy\engine\base.py", line 3288, in raw_connection
    return self.pool.connect()
  File "c:\users\jj_ca\onedrive\documents\github\project-phishing\venv\lib\site-packages\sqlalchemy\pool\base.py", line 452, in connect
    return _ConnectionFairy._checkout(self)
  File "c:\users\jj_ca\onedrive\documents\github\project-phishing\venv\lib\site-packages\sqlalchemy\pool\base.py", line 1267, in _checkout
    fairy = _ConnectionRecord.checkout(pool)
  File "c:\users\jj_ca\onedrive\documents\github\project-phishing\venv\lib\site-packages\sqlalchemy\pool\base.py", line 716, in checkout
    rec = pool._do_get()
  File "c:\users\jj_ca\onedrive\documents\github\project-phishing\venv\lib\site-packages\sqlalchemy\pool\impl.py", line 170, in _do_get
    self._dec_overflow()
  File "c:\users\jj_ca\onedrive\documents\github\project-phishing\venv\lib\site-packages\sqlalchemy\util\langhelpers.py", line 147, in __exit__
    raise exc_value.with_traceback(exc_tb)
  File "c:\users\jj_ca\onedrive\documents\github\project-phishing\venv\lib\site-packages\sqlalchemy\pool\impl.py", line 167, in _do_get
    return self._create_connection()
  File "c:\users\jj_ca\onedrive\documents\github\project-phishing\venv\lib\site-packages\sqlalchemy\pool\base.py", line 393, in _create_connection
    return _ConnectionRecord(self)
  File "c:\users\jj_ca\onedrive\documents\github\project-phishing\venv\lib\site-packages\sqlalchemy\pool\base.py", line 678, in __init__
    self.__connect()
  File "c:\users\jj_ca\onedrive\documents\github\project-phishing\venv\lib\site-packages\sqlalchemy\pool\base.py", line 903, in __connect
    pool.logger.debug("Error on connect(): %s", e)
  File "c:\users\jj_ca\onedrive\documents\github\project-phishing\venv\lib\site-packages\sqlalchemy\util\langhelpers.py", line 147, in __exit__
    raise exc_value.with_traceback(exc_tb)
  File "c:\users\jj_ca\onedrive\documents\github\project-phishing\venv\lib\site-packages\sqlalchemy\pool\base.py", line 898, in __connect
    self.dbapi_connection = connection = pool._invoke_creator(self)
  File "c:\users\jj_ca\onedrive\documents\github\project-phishing\venv\lib\site-packages\sqlalchemy\engine\create.py", line 637, in connect
    return dialect.connect(*cargs, **cparams)
  File "c:\users\jj_ca\onedrive\documents\github\project-phishing\venv\lib\site-packages\sqlalchemy\engine\default.py", line 615, in connect
    return self.loaded_dbapi.connect(*cargs, **cparams)
  File "c:\users\jj_ca\onedrive\documents\github\project-phishing\venv\lib\site-packages\MySQLdb\__init__.py", line 130, in Connect
    return Connection(*args, **kwargs)
  File "c:\users\jj_ca\onedrive\documents\github\project-phishing\venv\lib\site-packages\MySQLdb\connections.py", line 185, in __init__
    super().__init__(*args, **kwargs2)
MySQLdb._exceptions.OperationalError: (2002, "Can't connect to MySQL server on 'localhost' (10061)")

The above exception was the direct cause of the following exception:

Traceback (most recent call last):
  File "c:\users\jj_ca\onedrive\documents\github\project-phishing\venv\lib\site-packages\flask\app.py", line 2190, in wsgi_app
    response = self.full_dispatch_request()
  File "c:\users\jj_ca\onedrive\documents\github\project-phishing\venv\lib\site-packages\flask\app.py", line 1486, in full_dispatch_request
    rv = self.handle_user_exception(e)
  File "c:\users\jj_ca\onedrive\documents\github\project-phishing\venv\lib\site-packages\flask\app.py", line 1484, in full_dispatch_request
    rv = self.dispatch_request()
  File "c:\users\jj_ca\onedrive\documents\github\project-phishing\venv\lib\site-packages\flask\app.py", line 1469, in dispatch_request
    return self.ensure_sync(self.view_functions[rule.endpoint])(**view_args)
  File "C:\Users\jj_ca\OneDrive\Documents\GitHub\Project-Phishing\my_app\auth\views.py", line 40, in register
    if form.validate_on_submit():
  File "c:\users\jj_ca\onedrive\documents\github\project-phishing\venv\lib\site-packages\flask_wtf\form.py", line 86, in validate_on_submit
    return self.is_submitted() and self.validate(extra_validators=extra_validators)
  File "c:\users\jj_ca\onedrive\documents\github\project-phishing\venv\lib\site-packages\wtforms\form.py", line 329, in validate
    return super().validate(extra)
  File "c:\users\jj_ca\onedrive\documents\github\project-phishing\venv\lib\site-packages\wtforms\form.py", line 146, in validate
    if not field.validate(self, extra):
  File "c:\users\jj_ca\onedrive\documents\github\project-phishing\venv\lib\site-packages\wtforms\fields\core.py", line 242, in validate
    stop_validation = self._run_validation_chain(form, chain)
  File "c:\users\jj_ca\onedrive\documents\github\project-phishing\venv\lib\site-packages\wtforms\fields\core.py", line 262, in _run_validation_chain
    validator(form, self)
  File "C:\Users\jj_ca\OneDrive\Documents\GitHub\Project-Phishing\my_app\forms.py", line 24, in validate_username
    user = User.query.filter_by(username=username.data).first()
  File "c:\users\jj_ca\onedrive\documents\github\project-phishing\venv\lib\site-packages\sqlalchemy\orm\query.py", line 2747, in first
    return self.limit(1)._iter().first()  # type: ignore
  File "c:\users\jj_ca\onedrive\documents\github\project-phishing\venv\lib\site-packages\sqlalchemy\orm\query.py", line 2846, in _iter
    result: Union[ScalarResult[_T], Result[_T]] = self.session.execute(
  File "c:\users\jj_ca\onedrive\documents\github\project-phishing\venv\lib\site-packages\sqlalchemy\orm\session.py", line 2246, in execute
    return self._execute_internal(
  File "c:\users\jj_ca\onedrive\documents\github\project-phishing\venv\lib\site-packages\sqlalchemy\orm\session.py", line 2131, in _execute_internal
    conn = self._connection_for_bind(bind)
  File "c:\users\jj_ca\onedrive\documents\github\project-phishing\venv\lib\site-packages\sqlalchemy\orm\session.py", line 1998, in _connection_for_bind
    return trans._connection_for_bind(engine, execution_options)
  File "<string>", line 2, in _connection_for_bind
  File "c:\users\jj_ca\onedrive\documents\github\project-phishing\venv\lib\site-packages\sqlalchemy\orm\state_changes.py", line 139, in _go
    ret_value = fn(self, *arg, **kw)
  File "c:\users\jj_ca\onedrive\documents\github\project-phishing\venv\lib\site-packages\sqlalchemy\orm\session.py", line 1123, in _connection_for_bind
    conn = bind.connect()
  File "c:\users\jj_ca\onedrive\documents\github\project-phishing\venv\lib\site-packages\sqlalchemy\engine\base.py", line 3264, in connect
    return self._connection_cls(self)
  File "c:\users\jj_ca\onedrive\documents\github\project-phishing\venv\lib\site-packages\sqlalchemy\engine\base.py", line 147, in __init__
    Connection._handle_dbapi_exception_noconnection(
  File "c:\users\jj_ca\onedrive\documents\github\project-phishing\venv\lib\site-packages\sqlalchemy\engine\base.py", line 2426, in _handle_dbapi_exception_noconnection
    raise sqlalchemy_exception.with_traceback(exc_info[2]) from e
  File "c:\users\jj_ca\onedrive\documents\github\project-phishing\venv\lib\site-packages\sqlalchemy\engine\base.py", line 145, in __init__
    self._dbapi_connection = engine.raw_connection()
  File "c:\users\jj_ca\onedrive\documents\github\project-phishing\venv\lib\site-packages\sqlalchemy\engine\base.py", line 3288, in raw_connection
    return self.pool.connect()
  File "c:\users\jj_ca\onedrive\documents\github\project-phishing\venv\lib\site-packages\sqlalchemy\pool\base.py", line 452, in connect
    return _ConnectionFairy._checkout(self)
  File "c:\users\jj_ca\onedrive\documents\github\project-phishing\venv\lib\site-packages\sqlalchemy\pool\base.py", line 1267, in _checkout
    fairy = _ConnectionRecord.checkout(pool)
  File "c:\users\jj_ca\onedrive\documents\github\project-phishing\venv\lib\site-packages\sqlalchemy\pool\base.py", line 716, in checkout
    rec = pool._do_get()
  File "c:\users\jj_ca\onedrive\documents\github\project-phishing\venv\lib\site-packages\sqlalchemy\pool\impl.py", line 170, in _do_get
    self._dec_overflow()
  File "c:\users\jj_ca\onedrive\documents\github\project-phishing\venv\lib\site-packages\sqlalchemy\util\langhelpers.py", line 147, in __exit__
    raise exc_value.with_traceback(exc_tb)
  File "c:\users\jj_ca\onedrive\documents\github\project-phishing\venv\lib\site-packages\sqlalchemy\pool\impl.py", line 167, in _do_get
    return self._create_connection()
  File "c:\users\jj_ca\onedrive\documents\github\project-phishing\venv\lib\site-packages\sqlalchemy\pool\base.py", line 393, in _create_connection
    return _ConnectionRecord(self)
  File "c:\users\jj_ca\onedrive\documents\github\project-phishing\venv\lib\site-packages\sqlalchemy\pool\base.py", line 678, in __init__
    self.__connect()
  File "c:\users\jj_ca\onedrive\documents\github\project-phishing\venv\lib\site-packages\sqlalchemy\pool\base.py", line 903, in __connect
    pool.logger.debug("Error on connect(): %s", e)
  File "c:\users\jj_ca\onedrive\documents\github\project-phishing\venv\lib\site-packages\sqlalchemy\util\langhelpers.py", line 147, in __exit__
    raise exc_value.with_traceback(exc_tb)
  File "c:\users\jj_ca\onedrive\documents\github\project-phishing\venv\lib\site-packages\sqlalchemy\pool\base.py", line 898, in __connect
    self.dbapi_connection = connection = pool._invoke_creator(self)
  File "c:\users\jj_ca\onedrive\documents\github\project-phishing\venv\lib\site-packages\sqlalchemy\engine\create.py", line 637, in connect
    return dialect.connect(*cargs, **cparams)
  File "c:\users\jj_ca\onedrive\documents\github\project-phishing\venv\lib\site-packages\sqlalchemy\engine\default.py", line 615, in connect
    return self.loaded_dbapi.connect(*cargs, **cparams)
  File "c:\users\jj_ca\onedrive\documents\github\project-phishing\venv\lib\site-packages\MySQLdb\__init__.py", line 130, in Connect
    return Connection(*args, **kwargs)
  File "c:\users\jj_ca\onedrive\documents\github\project-phishing\venv\lib\site-packages\MySQLdb\connections.py", line 185, in __init__
    super().__init__(*args, **kwargs2)
sqlalchemy.exc.OperationalError: (MySQLdb._exceptions.OperationalError) (2002, "Can't connect to MySQL server on 'localhost' (10061)")
(Background on this error at: https://sqlalche.me/e/20/e3q8)
